Workbook
Name Slicer_Clean_Region: #N/A
Name Slicer_Month: #N/A
Name Slicer_Product: #N/A

Sheet Raw Sales Data
A1: Order ID | B1: Order Date | C1: Customer Name | D1: Region | E1: Product | F1: Category | G1: Quantity | H1: Unit Price | I1: Revenue | J1: Sales Channel | K1: Sales Rep
A2: O0001 | B2: 45846 | C2: Galaxy Tech | D2: South | E2: Keyboard | F2: Accessories | G2: 8 | H2: 1870 | I2: 14960 | J2: Distributor | K2: Priya
A3: O0002 | B3: 45788 | C3: Bright Solutions | D3: West | E3: Mouse | F3: Accessories | G3: 2 | H3: 850 | I3: 1700 | J3: Retail Store | K3: Vikram
A4: O0003 | B4: 45971 | C4: Lotus Enterprises | D4: North | E4: Laptop | F4: Electronics | G4: 10 | H4: 52980 | I4: 529800 | J4: Online | K4: Priya
A5: O0004 | B5: 45928 | C5: Orbit Retail | D5: South | E5: Tablet | F5: Electronics | G5: 1 | H5: 27070 | I5: 27070 | J5: Distributor | K5: Karan
A6: O0005 | B6: 45964 | C6: Galaxy Tech | D6: North | E6: Printer | F6: Office Equipment | G6: 4 | H6: 11590 | I6: 46360 | J6: Online | K6: Rahul
A7: O0006 | B7: 45922 | C7: Bright Solutions | D7: West | E7: Webcam | F7: Accessories | G7: 10 | H7: 3360 | I7: 33600 | J7: Distributor | K7: Karan
A8: O0007 | B8: 45863 | C8: QuickBuy Pvt Ltd | D8: West | E8: Laptop | F8: Electronics | G8: 3 | H8: 48130 | I8: 144390 | J8: Retail Store | K8: Karan
A9: O0008 | B9: 45967 | C9: Royal Traders | D9: South | E9: Keyboard | F9: Accessories | G9: 3 | H9: 1810 | I9: 5430 | J9: Retail Store | K9: Rahul
A10: O0009 | B10: 45872 | C10: Horizon Distributors | D10: North | E10: Desk | F10: Furniture | G10: 4 | H10: 12810 | I10: 51240 | J10: Online | K10: Rahul
A11: O0010 | B11: 45845 | C11: Metro Mart | D11: North | E11: Printer | F11: Office Equipment | G11: 4 | H11: 13430 | I11: 53720 | J11: Online | K11: Sneha
A12: O0011 | B12: 45793 | C12: Kaveri Stores | D12: East | E12: Laptop | F12: Electronics | G12: 10 | H12: 54270 | I12: 542700 | J12: Online | K12: Priya
A13: O0012 | B13: 45698 | C13: Galaxy Tech | D13: North | E13: Office Chair | F13: Furniture | G13: 4 | H13: 9080 | I13: 36320 | J13: Retail Store | K13: Anita
... A26: O0025 | B26: 45951 | C26: Evergreen Stores | D26: West | E26: Laptop | F26: Electronics | G26: 2 | H26: 49850 | I26: 99700 | J26: Retail Store | K26: Vikram
A27: O0026 | B27: 45858 | C27: Future Mart | D27: West | E27: Mouse | F27: Accessories | G27: 5 | H27: 940 | I27: 4700 | K27: Priya
A28: O0027 | B28: 45804 | C28: Vertex Retail | D28: West | E28: Tablet | F28: Electronics | G28: 4 | H28: 25830 | I28: 103320 | J28: Distributor | K28: Karan
A29: O0028 | B29: 46017 | C29: Alpha Traders | D29: East | E29: Webcam | F29: Accessories | G29: 2 | H29: 3210 | I29: 6420 | J29: Online | K29: Anita
A30: O0029 | B30: 45920 | C30: Prime Distributors | D30: South | E30: Monitor | F30: Electronics | G30: 3 | H30: 14950 | I30: 44850 | J30: Online | K30: Karan
A31: O0030 | B31: 45797 | C31: Evergreen Stores | D31: North | E31: Printer | F31: Office Equipment | G31: 2 | H31: 11690 | I31: 23380 | J31: Distributor | K31: Anita
A32: O0031 | B32: 45809 | C32: Alpha Traders | D32: West | E32: Keyboard | F32: Accessories | G32: 4 | H32: 1900 | I32: 7600 | J32: Distributor | K32: Anita
A33: O0032 | B33: 45884 | C33: Prime Distributors | D33: South | E33: Monitor | F33: Electronics | G33: 6 | H33: 14750 | I33: 88500 | J33: Online | K33: Priya
A34: O0033 | B34: 45851 | C34: Crest Retail | D34: West | E34: Webcam | F34: Accessories | G34: 2 | H34: 3100 | I34: 6200 | J34: Online | K34: Anita
A35: O0034 | B35: 45961 | C35: Vertex Retail | D35: West | E35: Monitor | F35: Electronics | G35: 1 | H35: 14490 | I35: 14490 | J35: Distributor | K35: Priya
A36: O0035 | B36: 45679 | C36: Nova Solutions | D36: South | E36: Tablet | F36: Electronics | G36: 3 | H36: 26180 | I36: 78540 | J36: Retail Store | K36: Vikram
A37: O0036 | B37: 45883 | C37: Alpha Traders | D37: West | E37: Mouse | F37: Accessories | G37: 6 | H37: 920 | I37: 5520 | J37: Distributor | K37: Anita
A38: O0037 | B38: 45692 | C38: QuickBuy Pvt Ltd | D38: West | E38: Monitor | F38: Electronics | G38: 4 | H38: 13990 | I38: 55960 | J38: Online | K38: Karan
A39: O0038 | B39: 45756 | C39: Iconic Retail | D39: North | E39: Webcam | F39: Accessories | G39: 8 | H39: 3410 | I39: 27280 | J39: Online | K39: Anita
... A74: O0073 | B74: 45774 | C74: Future Mart | D74: South | E74: Keyboard | F74: Accessories | G74: 2 | H74: 1910 | I74: 3820 | J74: Online | K74: Sneha
A75: O0074 | B75: 45860 | C75: Evergreen Stores | E75: Laptop | F75: Electronics | G75: 6 | H75: 52230 | I75: 313380 | J75: Distributor | K75: Priya
A76: O0075 | B76: 45671 | C76: Orbit Retail | D76: East | E76: Webcam | F76: Accessories | G76: 3 | H76: 3270 | I76: 9810 | J76: Online | K76: Sneha
A77: O0076 | B77: 45669 | C77: Jupiter Systems | D77: West | E77: Headphones | F77: Accessories | G77: 2 | H77: 2280 | I77: 4560 | J77: Retail Store | K77: Karan
A78: O0077 | B78: 45821 | C78: Horizon Distributors | D78: South | E78: Laptop | F78: Electronics | G78: 2 | H78: 49250 | I78: 98500 | J78: Retail Store | K78: Karan
A79: O0078 | B79: 45802 | C79: Iconic Retail | D79: North | E79: Laptop | F79: Electronics | G79: 10 | H79: 56050 | I79: 560500 | J79: Online | K79: Karan
A80: O0079 | B80: 45692 | C80: Future Mart | D80: South | E80: Tablet | F80: Electronics | G80: 2 | H80: 26360 | I80: 52720 | J80: Distributor | K80: Sneha
A81: O0080 | B81: 45899 | C81: Metro Mart | D81: North | E81: Tablet | F81: Electronics | G81: 3 | H81: 29940 | I81: 89820 | J81: Distributor | K81: Anita
A82: O0081 | B82: 45924 | C82: QuickBuy Pvt Ltd | D82: North | E82: Office Chair | F82: Furniture | G82: 3 | H82: 9160 | I82: 27480 | J82: Online | K82: Rahul
A83: O0082 | B83: 45968 | C83: Future Mart | D83: West | E83: Laptop | F83: Electronics | G83: 1 | H83: 47950 | I83: 47950 | J83: Online | K83: Sneha
A84: O0083 | B84: 45710 | C84: Evergreen Stores | D84: South | E84: Webcam | F84: Accessories | G84: 10 | H84: 3230 | I84: 32300 | J84: Retail Store | K84: Priya
A85: O0084 | B85: 45708 | C85: Metro Mart | D85: North | E85: Monitor | F85: Electronics | G85: 3 | H85: 13640 | I85: 40920 | J85: Retail Store | K85: Anita
A86: O0085 | B86: 45729 | C86: Galaxy Tech | D86: South | E86: Headphones | F86: Accessories | G86: 4 | H86: 2150 | I86: 8600 | J86: Retail Store | K86: Rahul
...

Sheet Project Guide
A1: Sales Data Analysis & Interactive Dashboard
A3: Project goal | B3: Clean raw sales data, analyze business performance, and build an interactive Excel dashboard.
A4: Important | B4: Do NOT edit Raw Sales Data. Create a copy named Cleaned Data and perform cleaning there.
A5: Resume scope | B5: Cleaning & validation | PivotTables | XLOOKUP/VLOOKUP | IF | SUMIFS | Filters | Conditional Formatting | KPIs | Charts | Slicers | Business insights
A6: Analysis areas | B6: Sales trends | Regional performance | Product-wise sales | Monthly revenue | Top products | Customer purchasing patterns | Sales opportunities

Sheet Cleaned Data
A1: Order ID | B1: Order Date | C1: Customer Name | D1: Clean Region | E1: Product | F1: Category | G1: Quantity | H1: Unit Price | I1: Revenue | J1: Sales Channel | K1: Sales Rep | L1: Cleaned Customer Name
A2: O0001 | B2: 45846 | C2: Galaxy Tech | D2: South | E2: Keyboard | F2: Accessories | G2: 8 | H2: 1870 | I2: 14960 | J2: Distributor | K2: Priya | L2: =TRIM(C2) -> Galaxy Tech
A3: O0002 | B3: 45788 | C3: Bright Solutions | D3: West | E3: Mouse | F3: Accessories | G3: 2 | H3: 850 | I3: 1700 | J3: Retail Store | K3: Vikram | L3: =TRIM(C3) -> Bright Solutions
A4: O0003 | B4: 45971 | C4: Lotus Enterprises | D4: North | E4: Laptop | F4: Electronics | G4: 10 | H4: 52980 | I4: 529800 | J4: Online | K4: Priya | L4: =TRIM(C4) -> Lotus Enterprises
A5: O0004 | B5: 45928 | C5: Orbit Retail | D5: South | E5: Tablet | F5: Electronics | G5: 1 | H5: 27070 | I5: 27070 | J5: Distributor | K5: Karan | L5: =TRIM(C5) -> Orbit Retail
A6: O0005 | B6: 45964 | C6: Galaxy Tech | D6: North | E6: Printer | F6: Office Equipment | G6: 4 | H6: 11590 | I6: 46360 | J6: Online | K6: Rahul | L6: =TRIM(C6) -> Galaxy Tech
A7: O0006 | B7: 45922 | C7: Bright Solutions | D7: West | E7: Webcam | F7: Accessories | G7: 10 | H7: 3360 | I7: 33600 | J7: Distributor | K7: Karan | L7: =TRIM(C7) -> Bright Solutions
A8: O0007 | B8: 45863 | C8: QuickBuy Pvt Ltd | D8: West | E8: Laptop | F8: Electronics | G8: 3 | H8: 48130 | I8: 144390 | J8: Retail Store | K8: Karan | L8: =TRIM(C8) -> QuickBuy Pvt Ltd
A9: O0008 | B9: 45967 | C9: Royal Traders | D9: South | E9: Keyboard | F9: Accessories | G9: 3 | H9: 1810 | I9: 5430 | J9: Retail Store | K9: Rahul | L9: =TRIM(C9) -> Royal Traders
A10: O0009 | B10: 45872 | C10: Horizon Distributors | D10: North | E10: Desk | F10: Furniture | G10: 4 | H10: 12810 | I10: 51240 | J10: Online | K10: Rahul | L10: =TRIM(C10) -> Horizon Distributors
A11: O0010 | B11: 45845 | C11: Metro Mart | D11: North | E11: Printer | F11: Office Equipment | G11: 4 | H11: 13430 | I11: 53720 | J11: Online | K11: Sneha | L11: =TRIM(C11) -> Metro Mart
A12: O0011 | B12: 45793 | C12: Kaveri Stores | D12: East | E12: Laptop | F12: Electronics | G12: 10 | H12: 54270 | I12: 542700 | J12: Online | K12: Priya | L12: =TRIM(C12) -> Kaveri Stores
A13: O0012 | B13: 45698 | C13: Galaxy Tech | D13: North | E13: Office Chair | F13: Furniture | G13: 4 | H13: 9080 | I13: 36320 | J13: Retail Store | K13: Anita | L13: =TRIM(C13) -> Galaxy Tech
... A301: O0300 | B301: 45711 | C301: Lotus Enterprises | D301: North | E301: Printer | F301: Office Equipment | G301: 1 | H301: 13020 | I301: 13020 | J301: Retail Store | K301: Vikram | L301: =TRIM(C301) -> Lotus Enterprises

Sheet Analysis
A1: KPI | B1: Value
A2: Total Revenue | B2: =SUM('Cleaned Data'!I2:I301) -> 18326410
A3: Total Orders | B3: =COUNTA('Cleaned Data'!A2:A301) -> 300 | F3: Row Labels | G3: 0
A4: Total Qnty Sold | B4: =SUM('Cleaned Data'!G2:G301) -> 1071 | F4: North | G4: 6264470
A5: Average Order Value | B5: =B2/B3 -> 61088.033 | F5: East | G5: 4463440
F6: South | G6: 3824470
F7: West | G7: 3460650
A8: Month | B8: Revenue | F8: Unknown | G8: 313380
A9: January | B9: =SUMIFS('Cleaned Data'!$I$2:$I$301,'Cleaned Data'!$B$2:$B$301,">="&DATE(2025,1,1),'Cleaned Data'!$B$2:$B$301,"<"&DATE(2025,2,1)) -> 1728820 | F9: Grand Total | G9: 18326410
A10: February | B10: =SUMIFS('Cleaned Data'!$I$2:$I$301,'Cleaned Data'!$B$2:$B$301,">="&DATE(2025,2,1),'Cleaned Data'!$B$2:$B$301,"<"&DATE(2025,3,1)) -> 1151990
A11: March | B11: =SUMIFS('Cleaned Data'!$I$2:$I$301,'Cleaned Data'!$B$2:$B$301,">="&DATE(2025,3,1),'Cleaned Data'!$B$2:$B$301,"<"&DATE(2025,4,1)) -> 1436990
A12: April | B12: =SUMIFS('Cleaned Data'!$I$2:$I$301,'Cleaned Data'!$B$2:$B$301,">="&DATE(2025,4,1),'Cleaned Data'!$B$2:$B$301,"<"&DATE(2025,5,1)) -> 1541050 | F12: Row Labels | G12: Sum of Revenue
A13: May | B13: =SUMIFS('Cleaned Data'!$I$2:$I$301,'Cleaned Data'!$B$2:$B$301,">="&DATE(2025,5,1),'Cleaned Data'!$B$2:$B$301,"<"&DATE(2025,6,1)) -> 2609370 | F13: January | G13: 1728820
A14: June | B14: =SUMIFS('Cleaned Data'!$I$2:$I$301,'Cleaned Data'!$B$2:$B$301,">="&DATE(2025,6,1),'Cleaned Data'!$B$2:$B$301,"<"&DATE(2025,7,1)) -> 1211550 | F14: February | G14: 1151990
A15: July | B15: =SUMIFS('Cleaned Data'!$I$2:$I$301,'Cleaned Data'!$B$2:$B$301,">="&DATE(2025,7,1),'Cleaned Data'!$B$2:$B$301,"<"&DATE(2025,8,1)) -> 1248590 | F15: March | G15: 1436990
A16: August | B16: =SUMIFS('Cleaned Data'!$I$2:$I$301,'Cleaned Data'!$B$2:$B$301,">="&DATE(2025,8,1),'Cleaned Data'!$B$2:$B$301,"<"&DATE(2025,9,1)) -> 840840 | F16: April | G16: 1541050
A17: September | B17: =SUMIFS('Cleaned Data'!$I$2:$I$301,'Cleaned Data'!$B$2:$B$301,">="&DATE(2025,9,1),'Cleaned Data'!$B$2:$B$301,"<"&DATE(2025,10,1)) -> 1773180 | F17: May | G17: 2609370
A18: October | B18: =SUMIFS('Cleaned Data'!$I$2:$I$301,'Cleaned Data'!$B$2:$B$301,">="&DATE(2025,10,1),'Cleaned Data'!$B$2:$B$301,"<"&DATE(2025,11,1)) -> 2185110 | F18: June | G18: 1211550
A19: November | B19: =SUMIFS('Cleaned Data'!$I$2:$I$301,'Cleaned Data'!$B$2:$B$301,">="&DATE(2025,11,1),'Cleaned Data'!$B$2:$B$301,"<"&DATE(2025,12,1)) -> 1518710 | F19: July | G19: 1248590
A20: December | B20: =SUMIFS('Cleaned Data'!$I$2:$I$301,'Cleaned Data'!$B$2:$B$301,">="&DATE(2025,12,1),'Cleaned Data'!$B$2:$B$301,"<"&DATE(2026,1,1)) -> 1080210 | F20: August | G20: 840840
F21: September | G21: 1773180
F22: October | G22: 2185110
A23: Region | B23: Revenue | F23: November | G23: 1518710
A24: North | B24: =SUMIFS('Cleaned Data'!$I$2:$I$301,'Cleaned Data'!$D$2:$D$301,A24) -> 6264470 | F24: December | G24: 1080210
A25: South | B25: =SUMIFS('Cleaned Data'!$I$2:$I$301,'Cleaned Data'!$D$2:$D$301,A25) -> 3824470 | F25: Grand Total | G25: 18326410
A26: East | B26: =SUMIFS('Cleaned Data'!$I$2:$I$301,'Cleaned Data'!$D$2:$D$301,A26) -> 4463440
A27: West | B27: =SUMIFS('Cleaned Data'!$I$2:$I$301,'Cleaned Data'!$D$2:$D$301,A27) -> 3460650
A29: Product | B29: Revenue | F29: Row Labels | G29: Sum of Revenue | J29: Product | K29: Category | L29: Unit Price
A30: Laptop | B30: =SUMIFS('Cleaned Data'!$I$2:$I$301,'Cleaned Data'!$E$2:$E$301,A30) -> 9864040 | F30: Desk | G30: 563040 | J30: Laptop | K30: Electronics | L30: =_xlfn.XLOOKUP(J30,'Cleaned Data'!$E$2:$E$301,'Cleaned Data'!$H$2:$H$301,"Not Found") -> 52980
A31: Tablet | B31: =SUMIFS('Cleaned Data'!$I$2:$I$301,'Cleaned Data'!$E$2:$E$301,A31) -> 3077220 | F31: Headphones | G31: 193390 | J31: Tablet | K31: Electronics | L31: =_xlfn.XLOOKUP(J31,'Cleaned Data'!$E$2:$E$301,'Cleaned Data'!$H$2:$H$301,"Not Found") -> 27070
A32: Monitor | B32: =SUMIFS('Cleaned Data'!$I$2:$I$301,'Cleaned Data'!$E$2:$E$301,A32) -> 1835660 | F32: Keyboard | G32: 198200 | J32: Monitor | K32: Electronics | L32: =_xlfn.XLOOKUP(J32,'Cleaned Data'!$E$2:$E$301,'Cleaned Data'!$H$2:$H$301,"Not Found") -> 14010
A33: Printer | B33: =SUMIFS('Cleaned Data'!$I$2:$I$301,'Cleaned Data'!$E$2:$E$301,A33) -> 1503960 | F33: Laptop | G33: 9864040 | J33: Printer | K33: Electronics | L33: =_xlfn.XLOOKUP(J33,'Cleaned Data'!$E$2:$E$301,'Cleaned Data'!$H$2:$H$301,"Not Found") -> 11590
A34: Office Chair | B34: =SUMIFS('Cleaned Data'!$I$2:$I$301,'Cleaned Data'!$E$2:$E$301,A34) -> 613170 | F34: Monitor | G34: 1835660 | J34: Office Chair | K34: Furniture | L34: =_xlfn.XLOOKUP(J34,'Cleaned Data'!$E$2:$E$301,'Cleaned Data'!$H$2:$H$301,"Not Found") -> 9080
A35: Desk | B35: =SUMIFS('Cleaned Data'!$I$2:$I$301,'Cleaned Data'!$E$2:$E$301,A35) -> 563040 | F35: Mouse | G35: 79390 | J35: Desk | K35: Furniture | L35: =_xlfn.XLOOKUP(J35,'Cleaned Data'!$E$2:$E$301,'Cleaned Data'!$H$2:$H$301,"Not Found") -> 12810
A36: Webcam | B36: =SUMIFS('Cleaned Data'!$I$2:$I$301,'Cleaned Data'!$E$2:$E$301,A36) -> 398340 | F36: Office Chair | G36: 613170 | J36: Webcam | K36: Electronics | L36: =_xlfn.XLOOKUP(J36,'Cleaned Data'!$E$2:$E$301,'Cleaned Data'!$H$2:$H$301,"Not Found") -> 3360
A37: Keyboard | B37: =SUMIFS('Cleaned Data'!$I$2:$I$301,'Cleaned Data'!$E$2:$E$301,A37) -> 198200 | F37: Printer | G37: 1503960 | J37: Keyboard | K37: Accessories | L37: =_xlfn.XLOOKUP(J37,'Cleaned Data'!$E$2:$E$301,'Cleaned Data'!$H$2:$H$301,"Not Found") -> 1870
A38: Headphones | B38: =SUMIFS('Cleaned Data'!$I$2:$I$301,'Cleaned Data'!$E$2:$E$301,A38) -> 193390 | F38: Tablet | G38: 3077220 | J38: Headphones | K38: Accessories | L38: =_xlfn.XLOOKUP(J38,'Cleaned Data'!$E$2:$E$301,'Cleaned Data'!$H$2:$H$301,"Not Found") -> 2130
A39: Mouse | B39: =SUMIFS('Cleaned Data'!$I$2:$I$301,'Cleaned Data'!$E$2:$E$301,A39) -> 79390 | F39: Webcam | G39: 398340 | J39: Mouse | K39: Accessories | L39: =_xlfn.XLOOKUP(J39,'Cleaned Data'!$E$2:$E$301,'Cleaned Data'!$H$2:$H$301,"Not Found") -> 850
F40: Grand Total | G40: 18326410
A41: Customer Name | B41: Revenue | C41: Order Count | D41: Average Order Value
...

Sheet Dashboard
B2: SALES DATA ANALYSIS & INTERACTIVE DASHBOARD
C4: TOTAL REVENUE | E4: TOTAL ORDERS | G4: TOTAL QUANTITY | I4: AVERAGE ORDER VALUE | S4: ORDER LOOKUP
C5: =Analysis!B2 -> 18326410 | E5: =Analysis!B3 -> 300 | G5: =Analysis!B4 -> 1071 | I5: 61088.033 | S5: Order ID | T5: O0003
S6: Product | T6: =_xlfn.XLOOKUP(T5,'Cleaned Data'!$A$2:$A$301,'Cleaned Data'!$E$2:$E$301,"Not Found") -> Laptop
S7: Customer | T7: =_xlfn.XLOOKUP(T5,'Cleaned Data'!$A$2:$A$301,'Cleaned Data'!$C$2:$C$301) -> Lotus Enterprises
S8: Revenue | T8: =_xlfn.XLOOKUP(T5,'Cleaned Data'!$A$2:$A$301,'Cleaned Data'!$I$2:$I$301) -> 529800
S9: Category | T9: =VLOOKUP(T5,'Cleaned Data'!$A$2:$F$301,6,FALSE) -> Electronics
